package exceptions;

import java.util.Scanner;

public class Main {
    public static void main(String[] args) {
        Scanner scanner = new Scanner(System.in);
//        //Arithmetic exception
//        int a = scanner.nextInt();
//        int b = scanner.nextInt();
//        int c = a / b;
//
//        System.out.println(c);

//        //ArrayIndexOutOfBoundException
//        int[] array = {10, 6, 5, 1, 43, 91, 7, 11};
//
//        for (int i = 0; i < 10; i++) {
//            System.out.println(array[i]);
//        }

//        //NullPointerException - NPE
//        Car car = CarShop.sell();
//
//        if (car != null) {
//            car.drive();
//        } else {
//            System.out.println("Сегодня домой пешком");
//        }

//        //OutOfMemory
//        List<Object[]> list = new ArrayList<>();
//
//        while (true) {
//            list.add(new Object[1_000_000]);
//        }

//        //try-catch
//        //в блоке try мы пишем код, где может возникнуть исключение
//        //а в блоке catch мы пишем, что делать, если возникнет исключение
//        int a;
//        int b;
//        int c;
//
//        try {
//            a = scanner.nextInt();
//            b = scanner.nextInt();
//            c = a / b;
//            System.out.println("Результат деления - " + c);
//        } catch (InputMismatchException oleg) {
//            oleg.printStackTrace();
//            System.out.println("У тебя руки из ...");
//        } catch (ArithmeticException e) {
//            System.out.println("На ноль делить нельзя!!!!!");
//        } finally {
//            //Суть блока finally в том, что прежде чем выполнится catch - отработает finally
//        }


    }
}
